Workbook

Sheet შეჯამება
B1: სასტუმროს მე-19 სართულის რემონტი — ბიუჯეტის შეჯამება
B2: ოთახები 1901–1919 (14 standard, 4 executive/business) + დერეფანი · ვალუტა: ლარი (GEL), დღგ 18% ჩათვლით
B3: ფასები გადამოწმებულია 13.08.2026 · კურსი: 1 EUR = 3.0205 ₾, 1 USD = 2.6181 ₾ (ეროვნული ბანკი) · იხ. „დაშვებები“ და „წყაროები“
B5: A. მიმდინარე სარემონტო სამუშაოები — ფაქტი და ვალდებულებები
B6: მუხლი | C6: თანხა (₾) | D6: აქედან გადახდილი (₾) | E6: შენიშვნა
B7: სამუშაოები | C7: =სამუშაო!F43 -> 33134.824 | D7: =სამუშაო!F46 -> 22819 | E7: IN-HOUSE სამუშაოები = 0 ₾ (სასტუმროს პერსონალი)
B8: შემსრულებლები (სამუშაოს ცხრილს გარეთ) | C8: =შემსრულებლები!E13 -> 2800 | D8: 0 | E8: გადაფარვის გარეშე — იხ. ფურცელი „შემსრულებლები“
B9: მასალები | C9: =მასალები!F68 -> 31101.9 | D9: =მასალები!F70 -> 29174.9 | E9: შეიცავს შეფასებულ (ჯერ შეუსყიდავ) პოზიციებსაც
B10: ინსტრუმენტები | C10: =ინსტრუმენტები!F7 -> 2930 | D10: =SUMIF(ინსტრუმენტები!G4:G6,"PAID",ინსტრუმენტები!F4:F6) -> 90 | E10: DeWalt-ის ფასები განახლებულია ოფიციალურ ფასებზე — ეკონომია 845 ₾
B11: სულ მიმდინარე ეტაპი (A) | C11: =SUM(C7:C10) -> 69966.724 | D11: =SUM(D7:D10) -> 52083.9
B12: დარჩენილი გადასახდელი (A) | C12: =C11-D11 -> 17882.824
B14: B. სრული განახლების საპროგნოზო ბიუჯეტი (18 ოთახი + დერეფანი)
B15: მუხლი | C15: თანხა (₾) | E15: შენიშვნა
B16: შუალედური ჯამი (ოთახები + დერეფანი + ნაგვის გატანა) | C16: =Total!F9 -> 242830.04 | E16: 14 × standard, 4 × executive, დერეფანი
B17: გაუთვალისწინებელი ხარჯი (10%) | C17: =Total!F10 -> 24283.004 | E17: დარგობრივი ნორმა
B18: სულ საპროგნოზო ბიუჯეტი (B) | C18: =Total!F11 -> 267113.04 | E18: =C18/დაშვებები!$D$6 -> 88433.387
B20: C. გამოვლენილი ეკონომია — სად იხდით საბაზროზე მეტს
B21: პოზიცია | C21: ბიუჯეტში (₾) | D21: ბაზარზე (₾) | E21: პოტენციური ეკონომია
B22: პერფორატორი DeWalt პატარა + დიდი (1+1 ც.) | C22: 3685 | D22: 2840 | E22: dewaltshop.ge ოფიციალური ფასი — უკვე გასწორებულია ამ ფაილში
B23: ლაქი პრიალა აეროზოლი (86 ბალონი) | C23: 6999.4 | D23: 1978 | E23: 81.4 ₾ vs Novol 23 ₾ (17 ₾ 6+ ც.) — შესყიდვამდე გადაამოწმეთ სპეციფიკაცია
B24: დუში პატარა, ხელის (18 ნომერი) | C24: 5400 | D24: 3240 | E24: 300 ₾ vs Grohe Vitalio კომპლექტი 180 ₾ (domino.com.ge)
B25: Sista გამჭვირვალე სილიკონი (20 ყუთი) | C25: 400 | D25: 244 | E25: 20 ₾ vs Soudal/Sista 12.2–14 ₾
B26: აბაზანის ნიჟარის სიფონი (10 ც.) | C26: 1140 | D26: 870 | E26: 114 ₾ vs Geberit 87 ₾ (gorgia.ge)
B27: ცემენტი, ნაგვის ტომრები, WD-40 და სხვ. წვრილმანი | E27: ნაწილი ძვირია, ნაწილი იაფად არის ჩადებული — დეტალები „მასალები“ ფურცელზე
B28: სულ პოტენციური ეკონომია | C28: =SUM(C22:C27) -> 17624.4 | D28: =SUM(D22:D27) -> 9172 | E28: =C28-D28 -> 8452.4
B30: მეთოდოლოგია და შენიშვნები
B31: • A და B სხვადასხვა მოცულობაა: A — მიმდინარე ეტაპის ფაქტობრივი/ნაკისრი ხარჯები; B — მომავალი სრული განახლების საბაზრო შეფასება (მასალა + სამუშაო).
B32: • ყველა ერთეულის ფასი გადამოწმებულია 13.08.2026 ქართულ საცალო წყაროებზე (gorgia.ge, domino.com.ge, parketi.ge, bona.com.ge, dewaltshop.ge და სხვ.) — სრული სია ფურცელზე „წყაროები“.
B33: • გასწორებულია ძველი ფაილის შეცდომები: (1) ხარჯაღრიცხვის ფურცელი მასალების ჯამს კარგავდა (ცარიელ F69-ს იშველიებდა) — მასალები ≈30,303 ₾ ჯამში არ ჯდებოდა; (2) standard ოთახში საღებავის სტრიქონი (125 ₾) ჯამში არ იყო; (3) 12 პოზიციას ფასი საერთოდ არ ჰქონდა — შევსებულია საბაზრო შეფასებით.
B34: • ლეგენდა: ლურჯი — შესაყვანი/ფაქტობრივი მონაცემი · შავი — ფორმულა · მწვანე — ბმული სხვა ფურცელზე · ყვითელი ფონი — საკვანძო დაშვება ან ჯამი.

Sheet დაშვებები
B1: დაშვებები და ფასების ცნობარი / Assumptions & Price Book
B2: ყველა ფასი — ლარი (GEL), დღგ (18%) ჩათვლით. გადამოწმებულია 13.08.2026.
B4: 1. გლობალური დაშვებები
A5: N | B5: პარამეტრი | C5: განზ. | D5: მნიშვნ. | E5: წყარო | F5: სტატუსი | G5: შენიშვნა
A6: 1 | B6: ვალუტის კურსი EUR/GEL | C6: ლარი | D6: 3.0205 | E6: საქართველოს ეროვნული ბანკი (nbg.gov.ge API) | F6: გადამოწმებული | G6: ოფიციალური კურსი 13.08.2026
A7: 2 | B7: ვალუტის კურსი USD/GEL | C7: ლარი | D7: 2.6181 | E7: საქართველოს ეროვნული ბანკი (nbg.gov.ge API) | F7: გადამოწმებული | G7: ოფიციალური კურსი 13.08.2026
A8: 3 | B8: დღგ (VAT) | C8: % | D8: 0.18 | E8: საგადასახადო კოდექსი | F8: კანონით | G8: საცალო ფასები დღგ-ს უკვე მოიცავს — ცალკე არ ემატება
A9: 4 | B9: გაუთვალისწინებელი ხარჯი (contingency) | C9: % | D9: 0.1 | E9: დარგობრივი ნორმა: 5–10%; სასტუმროსთვის იმპორტით — 10–15% | F9: შეფასება | G9: გამოიყენება Total ფურცელზე
A10: 5 | B10: იმპორტის ფრახტი/მოსაკრებელი (EU საქონელი) | C10: % | D10: 0.1 | E10: ტიპური დანამატი EU ონლაინ-ფასზე (ფრახტი+განბაჟება) | F10: შეფასება | G10: ემატება Artemide-ს და LANO ხალიჩას
A11: 6 | B11: მასალის დანაკარგი — პარკეტი (waste) | C11: % | D11: 0.07 | E11: სამონტაჟო პრაქტიკა (ჭრა/წუნი 5–10%) | F11: შეფასება | G11: ემატება პარკეტის რაოდენობას BOQ-ში
B13: 2. ფასების ცნობარი (ერთეულის ფასები, ლარი დღგ-ით)
A14: N | B14: დასახელება | C14: განზ. | D14: ფასი (₾) | E14: წყარო | F14: სტატუსი | G14: შენიშვნა
A15: 1 | B15: პარკეტი მუხის მასიური, Exclusive ხარისხი | C15: კვ.მ | D15: 140 | E15: parketi.ge — Oak Parquet Exclusive | F15: გადამოწმებული | G15: Rustic 75 ₾ / Select 99 ₾ / Exclusive 140 ₾; სამშრიანი ინჟინრული 179–269 ₾
A16: 2 | B16: პარკეტის დაგება (სამუშაო) | C16: კვ.მ | D16: 45 | E16: homeis.ge; ბაზრის დიაპაზონი 25–65 ₾ | F16: გადამოწმებული | G16: კომპანია 30–65 ₾, კერძო ოსტატი 25–60 ₾
A17: 3 | B17: იატაკის ლაქი Bona Mega EVO | C17: ლიტრი | D17: 76 | E17: bona.com.ge — ოფიც. დისტრიბუტორი (380 ₾ / 5ლ) | F17: გადამოწმებული | G17: 2K Traffic კლასი ~100 ₾/ლ — დერეფნებისთვის
A18: 4 | B18: ფანერა არყის 10მმ, 1525×1525 | C18: ცალი | D18: 34 | E18: ecowood.ge | F18: გადამოწმებული | G18: 8მმ — 29 ₾, 12მმ — 41 ₾
A19: 5 | B19: პლინტუსი MDF თეთრი — მასალა+მონტაჟი+შეღებვა | C19: მეტრი | D19: 25 | E19: domino.com.ge (მასალა 10–15 ₾/მ) + სამუშაო | F19: გადამოწმებული | G19: მხოლოდ მასალა 10–15 ₾/მ; 25 ₾ = სრული ღირებულება
A20: 6 | B20: ლოგინის გვერდითა ტუმბო | C20: ცალი | D20: 230 | E20: veli.store (SONGMICS 2ც — 459.95 ₾); liva.ge 200 ₾ | F20: გადამოწმებული | G20: ძველი ბიუჯეტის 120 ₾ საცალო ფასზე დაბალია
A21: 7 | B21: ტელევიზორის სადგამი მაგიდა | C21: ცალი | D21: 250 | E21: liva.ge (~200 ₾); embawood.ge | F21: ნაწილობრივ | G21: დიაპაზონი 200–450 ₾
A22: 8 | B22: დუში დიდი (ზედა შხაპი 250მმ) | C22: ცალი | D22: 389 | E22: domino.com.ge — AM.PM Like 250×250 | F22: გადამოწმებული | G22: Rubineta 131 ₾; Grohe სისტემა 599–959 ₾
A23: 9 | B23: დუში პატარა (ხელის, Grohe კომპლექტი) | C23: ცალი | D23: 180 | E23: domino.com.ge — Grohe Vitalio Comfort ბარით | F23: გადამოწმებული | G23: ყურმილი ცალკე 63–103 ₾ (gorgia.ge); ძველი 300 ₾ — ~2×-ით მაღალი
A24: 10 | B24: შემრევი ონკანი (Grohe Get) | C24: ცალი | D24: 306 | E24: gorgia.ge — Grohe Get 23454000 (305.50 ₾) | F24: გადამოწმებული | G24: StartEdge 187 ₾, Eurosmart S 254 ₾, Get 306–379 ₾
A25: 11 | B25: ARTEMIDE სანათი დიდი (Tolomeo Terra) | C25: ცალი | D25: =ROUND(488*$D$6*(1+$D$10),0) -> 1621 | E25: light11.eu 488 € (RRP 610 €) + ფრახტი 10% | F25: გადამოწმებული (EU) | G25: EU ფასი × EUR კურსი × (1+ფრახტი); LED ვერსია 644 €
A26: 12 | B26: ARTEMIDE სანათი პატარა (Tolomeo Micro Parete) | C26: ცალი | D26: =ROUND(282*$D$6*(1+$D$10),0) -> 937 | E26: light11.eu 282 € + ფრახტი 10% | F26: გადამოწმებული (EU) | G26: ძველი ბიუჯეტის 633 ₾ დღეს 10–20%-ით ნაკლებია რეალურზე
A27: 13 | B27: კარი ოთახის (MDF ბლოკი კოლოფით + ფურნიტურა) | C27: ცალი | D27: 750 | E27: domino.com.ge — KMF 649–699 ₾ + სახელური/საკეტი ~50–150 ₾ | F27: გადამოწმებული | G27: პრემიუმ Terminus 1029–1499 ₾
A28: 14 | B28: კარი აბაზანის (700მმ, ტენმედეგი PVC-MDF) | C28: ცალი | D28: 359 | E28: domino.com.ge — Flydoors LA STELLA | F28: გადამოწმებული | G28: ეკონომ 179–199 ₾; KMF 649 ₾
A29: 15 | B29: სამღებრო სამუშაოები (მოშპაკვლა+შეღებვა) | C29: კვ.მ | D29: 20 | E29: remonti-mshenebloba.ge; euroremonti.ge; servisebi.ge | F29: გადამოწმებული | G29: დიაპაზონი 12–20 ₾/კვ.მ; 20 ₾ = სასტუმროს ხარისხი სრული მომზადებით
A30: 16 | B30: საღებავი StoColor In (ინტერიერის) | C30: ლიტრი | D30: 25 | E30: sto.ge (ფასი მოთხოვნით); EU საცალო ~15–18 ₾/ლ + იმპორტი | F30: შეფასება | G30: უსაფრთხო საბიუჯეტო ფასი საქართველოსთვის 20–28 ₾/ლ
A31: 17 | B31: ხალიჩა LANO (სასტუმროს კლასი, 19 €/კვ.მ) | C31: კვ.მ | D31: =ROUND(19*$D$6*(1+$D$10),2) -> 63.13 | E31: LANO — საპროექტო იმპორტი; domino.com.ge ბელგიური 10.5–119 ₾ | F31: ნაწილობრივ | G31: 19 € × EUR კურსი × (1+ფრახტი)
A32: 18 | B32: ხალიჩის დაგება (სამუშაო) | C32: კვ.მ | D32: 15 | E32: gurus.ge (ლამინატი 10–25 ₾ — პროქსი) | F32: შეფასება | G32: წებოზე დაგება ≤ ლამინატის ტარიფი
A33: 19 | B33: სარკე ზომაზე ჭრით + მონტაჟი | C33: კვ.მ | D33: 140 | E33: serwish.ge (მასალა 40–50 ₾-დან; დამუშავება+მონტაჟი) | F33: შეფასება | G33: რეალური სრული ფასი თბილისში 100–180 ₾/კვ.მ
A34: 20 | B34: სამშენებლო ნაგვის გატანა | C34: მ³ | D34: 370 | E34: demontaji.ge — 2026 წლის ტარიფი | F34: გადამოწმებული | G34: პარკეტის აყრა ცალკე — 2 ₾/კვ.მ
A35: 21 | B35: მოციკლოვება + გალაქვა (სამუშაო) | C35: კვ.მ | D35: 20 | E35: shop.glimtrex.ge (გერმანული აპარატი) | F35: გადამოწმებული | G35: სრული ციკლი მასალით 40–45 ₾/კვ.მ
B37: ლეგენდა: ლურჯი — შესაყვანი მონაცემი/ფაქტი · შავი — ფორმულა · მწვანე — ბმული სხვა ფურცელზე · ყვითელი ფონი — საკვანძო დაშვება.

Sheet standard
B1: STANDARD ROOM — ერთი ოთახის ხარჯთაღრიცხვა
B2: ფასები: ლარი, დღგ-ით — წყაროები ფურცელზე „დაშვებები“ და „წყაროები“.
A4: N | B4: დასახელება | C4: განზ. | D4: რაოდ. | E4: ერთ. ფასი (₾) | F4: ღირებულება (₾) | G4: შენიშვნა
A5: 1 | B5: პარკეტის დაგება | C5: კვ.მ | D5: 18 | E5: =დაშვებები!$D$16 -> 45 | F5: =D5*E5 -> 810 | G5: ოთახის ფართობი
A6: 2 | B6: პარკეტი მუხის Exclusive | C6: კვ.მ | D6: =ROUND(D5*(1+დაშვებები!$D$11),1) -> 19.3 | E6: =დაშვებები!$D$15 -> 140 | F6: =D6*E6 -> 2702 | G6: ფართობი + 7% დანაკარგი
A7: 3 | B7: ლაქი იატაკის Bona Mega EVO | C7: ლიტრი | D7: 6 | E7: =დაშვებები!$D$17 -> 76 | F7: =D7*E7 -> 456
A8: 4 | B8: ფანერა არყის 10მმ | C8: ცალი | D8: 7 | E8: =დაშვებები!$D$18 -> 34 | F8: =D8*E8 -> 238
A9: 5 | B9: პლინტუსი MDF (მასალა+მონტაჟი+შეღებვა) | C9: მეტრი | D9: 15 | E9: =დაშვებები!$D$19 -> 25 | F9: =D9*E9 -> 375
A10: 6 | B10: ლოგინის გვერდითა ტუმბოები | C10: ცალი | D10: 2 | E10: =დაშვებები!$D$20 -> 230 | F10: =D10*E10 -> 460
A11: 7 | B11: ტელევიზორის სადგამი მაგიდა | C11: ცალი | D11: 1 | E11: =დაშვებები!$D$21 -> 250 | F11: =D11*E11 -> 250
A12: 8 | B12: დუში დიდი (250მმ) | C12: ცალი | D12: 1 | E12: =დაშვებები!$D$22 -> 389 | F12: =D12*E12 -> 389
A13: 9 | B13: დუში პატარა (ხელის) | C13: ცალი | D13: 1 | E13: =დაშვებები!$D$23 -> 180 | F13: =D13*E13 -> 180
A14: 10 | B14: შემრევი ონკანი Grohe | C14: ცალი | D14: 1 | E14: =დაშვებები!$D$24 -> 306 | F14: =D14*E14 -> 306
A15: 11 | B15: ARTEMIDE სანათი დიდი | C15: ცალი | D15: 1 | E15: =დაშვებები!$D$25 -> 1621 | F15: =D15*E15 -> 1621 | G15: EUR ფასი — კურსზეა მიბმული
A16: 12 | B16: ARTEMIDE სანათი პატარა | C16: ცალი | D16: 2 | E16: =დაშვებები!$D$26 -> 937 | F16: =D16*E16 -> 1874 | G16: EUR ფასი — კურსზეა მიბმული
A17: 13 | B17: კარი ოთახის | C17: ცალი | D17: 1 | E17: =დაშვებები!$D$27 -> 750 | F17: =D17*E17 -> 750
A18: 14 | B18: კარი აბაზანის | C18: ცალი | D18: 1 | E18: =დაშვებები!$D$28 -> 359 | F18: =D18*E18 -> 359
A19: 15 | B19: სამღებრო სამუშაოები | C19: კვ.მ | D19: 40 | E19: =დაშვებები!$D$29 -> 20 | F19: =D19*E19 -> 800 | G19: კედლები+ჭერი
A20: 16 | B20: საღებავი StoColor | C20: ლიტრი | D20: 5 | E20: =დაშვებები!$D$30 -> 25 | F20: =D20*E20 -> 125 | G20: ძველ ფაილში ეს სტრიქონი ჯამში არ იყო ჩართული — გასწორებულია
B21: ჯამი | F21: =SUM(F5:F20) -> 11695
B23: ×14 ოთახი — იხ. ფურცელი „Total“.

Sheet executive
B1: EXECUTIVE ROOM — ერთი ოთახის ხარჯთაღრიცხვა
B2: ფასები: ლარი, დღგ-ით — წყაროები ფურცელზე „დაშვებები“ და „წყაროები“.
A4: N | B4: დასახელება | C4: განზ. | D4: რაოდ. | E4: ერთ. ფასი (₾) | F4: ღირებულება (₾) | G4: შენიშვნა
A5: 1 | B5: პარკეტის დაგება | C5: კვ.მ | D5: 28 | E5: =დაშვებები!$D$16 -> 45 | F5: =D5*E5 -> 1260 | G5: ოთახის ფართობი
A6: 2 | B6: პარკეტი მუხის Exclusive | C6: კვ.მ | D6: =ROUND(D5*(1+დაშვებები!$D$11),1) -> 30 | E6: =დაშვებები!$D$15 -> 140 | F6: =D6*E6 -> 4200 | G6: ფართობი + 7% დანაკარგი
A7: 3 | B7: ლაქი იატაკის Bona Mega EVO | C7: ლიტრი | D7: 8 | E7: =დაშვებები!$D$17 -> 76 | F7: =D7*E7 -> 608
A8: 4 | B8: ფანერა არყის 10მმ | C8: ცალი | D8: 10 | E8: =დაშვებები!$D$18 -> 34 | F8: =D8*E8 -> 340
A9: 5 | B9: პლინტუსი MDF (მასალა+მონტაჟი+შეღებვა) | C9: მეტრი | D9: 22 | E9: =დაშვებები!$D$19 -> 25 | F9: =D9*E9 -> 550
A10: 6 | B10: ლოგინის გვერდითა ტუმბოები | C10: ცალი | D10: 2 | E10: =დაშვებები!$D$20 -> 230 | F10: =D10*E10 -> 460
A11: 7 | B11: ტელევიზორის სადგამი მაგიდა | C11: ცალი | D11: 1 | E11: =დაშვებები!$D$21 -> 250 | F11: =D11*E11 -> 250
A12: 8 | B12: დუში დიდი (250მმ) | C12: ცალი | D12: 1 | E12: =დაშვებები!$D$22 -> 389 | F12: =D12*E12 -> 389
A13: 9 | B13: დუში პატარა (ხელის) | C13: ცალი | D13: 1 | E13: =დაშვებები!$D$23 -> 180 | F13: =D13*E13 -> 180
A14: 10 | B14: შემრევი ონკანი Grohe | C14: ცალი | D14: 2 | E14: =დაშვებები!$D$24 -> 306 | F14: =D14*E14 -> 612
A15: 11 | B15: ARTEMIDE სანათი დიდი | C15: ცალი | D15: 1 | E15: =დაშვებები!$D$25 -> 1621 | F15: =D15*E15 -> 1621
A16: 12 | B16: ARTEMIDE სანათი პატარა | C16: ცალი | D16: 2 | E16: =დაშვებები!$D$26 -> 937 | F16: =D16*E16 -> 1874
A17: 13 | B17: კარი ოთახის | C17: ცალი | D17: 1 | E17: =დაშვებები!$D$27 -> 750 | F17: =D17*E17 -> 750
A18: 14 | B18: კარი აბაზანის | C18: ცალი | D18: 1 | E18: =დაშვებები!$D$28 -> 359 | F18: =D18*E18 -> 359
A19: 15 | B19: სამღებრო სამუშაოები | C19: კვ.მ | D19: 60 | E19: =დაშვებები!$D$29 -> 20 | F19: =D19*E19 -> 1200 | G19: კედლები+ჭერი
A20: 16 | B20: საღებავი StoColor | C20: ლიტრი | D20: 7.5 | E20: =დაშვებები!$D$30 -> 25 | F20: =D20*E20 -> 187.5
B21: ჯამი | F21: =SUM(F5:F20) -> 14840.5
B23: ×4 ოთახი — იხ. ფურცელი „Total“.

Sheet corridor
B1: CORRIDOR — დერეფნის ხარჯთაღრიცხვა
B2: ფასები: ლარი, დღგ-ით — წყაროები ფურცელზე „დაშვებები“ და „წყაროები“.
A4: N | B4: დასახელება | C4: განზ. | D4: რაოდ. | E4: ერთ. ფასი (₾) | F4: ღირებულება (₾) | G4: შენიშვნა
A5: 1 | B5: სამღებრო სამუშაოები | C5: კვ.მ | D5: 250 | E5: =დაშვებები!$D$29 -> 20 | F5: =D5*E5 -> 5000 | G5: კედლები+ჭერი
A6: 2 | B6: საღებავი StoColor | C6: ლიტრი | D6: 30 | E6: =დაშვებები!$D$30 -> 25 | F6: =D6*E6 -> 750
A7: 3 | B7: ხალიჩა LANO (19 €/კვ.მ) | C7: კვ.მ | D7: 108 | E7: =დაშვებები!$D$31 -> 63.13 | F7: =D7*E7 -> 6818.04 | G7: EUR კურსზეა მიბმული
A8: 4 | B8: ხალიჩის დაგება | C8: კვ.მ | D8: 108 | E8: =დაშვებები!$D$32 -> 15 | F8: =D8*E8 -> 1620
B9: ჯამი | F9: =SUM(F5:F8) -> 14188.04

Sheet Total
B1: სრული განახლების საპროგნოზო ბიუჯეტი — მე-19 სართული
B2: 14 standard + 4 executive + დერეფანი. ფასები: ლარი, დღგ-ით, 13.08.2026.
A4: N | B4: დასახელება | C4: განზ. | D4: რაოდ. | E4: ერთ. ფასი (₾) | F4: ღირებულება (₾) | G4: შენიშვნა
A5: 1 | B5: standard room | C5: ოთახი | D5: 14 | E5: =standard!F21 -> 11695 | F5: =D5*E5 -> 163730
A6: 2 | B6: executive room | C6: ოთახი | D6: 4 | E6: =executive!F21 -> 14840.5 | F6: =D6*E6 -> 59362
A7: 3 | B7: corridor | C7: კომპლ. | D7: 1 | E7: =corridor!F9 -> 14188.04 | F7: =D7*E7 -> 14188.04
A8: 4 | B8: სამშენებლო ნაგვის გატანა (დემონტაჟის ნარჩენი) | C8: მ³ | D8: 15 | E8: =დაშვებები!$D$34 -> 370 | F8: =D8*E8 -> 5550 | G8: შეფასება: ~0.05 მ³/კვ.მ დემონტაჟის ნარჩენი; ტარიფი demontaji.ge
B9: შუალედური ჯამი | F9: =SUM(F5:F8) -> 242830.04
B10: გაუთვალისწინებელი ხარჯი (10%) | F10: =F9*დაშვებები!$D$9 -> 24283.004 | G10: იხ. დაშვება N4 — დარგობრივი ნორმა
B11: სულ ჯამი (GRAND TOTAL) | F11: =F9+F10 -> 267113.04 | G11: დღგ ჩათვლით
B12: ექვივალენტი EUR | F12: =F11/დაშვებები!$D$6 -> 88433.387 | G12: NBG კურსით 13.08.2026
B14: შენიშვნა: ძველი ვერსიის ჯამი იყო 216,216 ₾. სხვაობა აიხსნება: ნაგვის გატანა (ადრე საერთოდ არ იყო), 10% გაუთვალისწინებელი ხარჯი, standard ოთახის საღებავის სტრიქონი (ადრე ჯამში არ შედიოდა) და ერთეულის ფასების განახლება 13.08.2026 ბაზარზე.

Sheet სამუშაო
B1: შესრულებული და მიმდინარე სამუშაოები (ფაქტი/ვალდებულებები)
B2: IN-HOUSE = სასტუმროს პერსონალი — ფულადი ხარჯი 0 ₾. PAID სტრიქონები — ფაქტობრივი (ისტორიული) ფასები.
A4: N | B4: სამუშაოს დასახელება | C4: განზ. | D4: ერთ. ღირ. (₾) | E4: რაოდ. | F4: ღირებულება (₾) | G4: გადახდა | H4: სტატუსი | I4: შენიშვნა
A5: 1 | B5: თეთრი პანელების დაშპაკვლა, შეღებვა | C5: კვ.მ | D5: — | F5: 0 | G5: IN-HOUSE | H5: IN PROCESS
A6: 2 | B6: მაგიდების, კარადების, ნალიშნიკების შეღებვა | C6: ც. | D6: — | F6: 0 | G6: IN-HOUSE | H6: IN PROCESS
A7: 3 | B7: სილიკონის მოჭრა, დაფუგვა აბაზანის | D7: — | F7: 0 | G7: IN-HOUSE | H7: DONE
A8: 4 | B8: ჭერის ჩამოჭრა | C8: კვ.მ | D8: — | F8: 0 | G8: IN-HOUSE | H8: DONE
A9: 5 | B9: შეღებვა აბაზანის და ნომრის ჭერის | C9: ნომ. | D9: — | E9: 18 | F9: 0 | G9: IN-HOUSE | H9: DONE
A10: 6 | B10: აქსესუარების გადამაგრება ნომერში | C10: ნომ. | D10: — | E10: 18 | F10: 0 | G10: IN-HOUSE | H10: IN PROCESS
A11: 7 | B11: ხელსაბანის ნიჟარის პანელების გალაქვა | D11: — | F11: 0 | G11: IN-HOUSE | H11: IN PROCESS
A12: 8 | B12: დერეფნის შეღებვა | C12: ნომ. | D12: — | E12: 18 | F12: 0 | G12: IN-HOUSE | H12: IN PROCESS
A13: 9 | B13: ხალიჩის აღება | D13: — | F13: 0 | G13: IN-HOUSE | H13: IN PROCESS
A14: 10 | B14: ხალიჩის დაგება | C14: სართ. | D14: — | E14: 1 | F14: 1000 | G14: UNPAID | H14: IN PROCESS | I14: ფიქსირებული შეთანხმებული ფასი (მე-19 სართული)
A15: 11 | B15: ფანკოილის ძრავების შეცვლა | D15: — | F15: 0 | G15: IN-HOUSE | H15: DONE
A16: 12 | B16: კონდენსატორების შეცვლა | D16: — | F16: 0 | G16: IN-HOUSE | H16: DONE
A17: 13 | B17: მინი ბარების უკან ამოჭრა და გაწმენდა | D17: — | F17: 0 | G17: IN-HOUSE | H17: IN PROCESS
A18: 14 | B18: იმპულსორების გადამოწმება, ელექტროობის | D18: — | F18: 0 | G18: IN-HOUSE | H18: DONE
A19: 15 | B19: იატაკის მოციკლოვება, გალაქვა | D19: — | F19: 0 | G19: IN-HOUSE | H19: IN PROCESS
A20: 16 | B20: პარკეტის დაფის იატაკის დემონტაჟი (1901; 1902; 1907; 1909; 1910; 1916; 1918; 1919) | C20: კვ.მ | D20: — | E20: 162 | F20: 500 | G20: PAID | H20: DONE | I20: ფაქტი: 500 ₾ კონტრაქტი (≈3.1 ₾/კვ.მ; ბაზარი 2 ₾/კვ.მ — demontaji.ge)
A21: 17 | B21: პლინტუსის შეღებვა | D21: — | F21: 0 | G21: IN-HOUSE | H21: IN PROCESS
A22: 18 | B22: მარაცის ქვის დაგება | C22: კვ.მ | D22: 80 | E22: 30 | F22: =D22*E22 -> 2400 | G22: PAID | H22: DONE | I22: ფაქტი; ბაზარი: სტანდარტი 30–60 ₾, პრემიუმ მარმარილო ~80 ₾ (servisebi.ge)
A23: 19 | B23: მაგიდის დემონტაჟი, მონტაჟი | D23: — | F23: 0 | G23: IN-HOUSE | H23: IN PROCESS
A24: 20 | B24: ფანჯრების შემოწმება, შეკეთება | C24: ც. | D24: 50 | E24: 8 | F24: =D24*E24 -> 400 | G24: UNPAID | H24: IN PROCESS
A25: 21 | B25: საფარდე კარნიზის გადამაგრება | D25: — | F25: 0 | G25: IN-HOUSE | H25: DONE
A26: 22 | B26: კარადის კარის პეტლების შეკეთება | D26: — | F26: 0 | G26: IN-HOUSE | H26: DONE
A27: 23 | B27: ფანკოილის რადიატორის გაწმენდა | D27: — | F27: 0 | G27: IN-HOUSE | H27: DONE
A28: 24 | B28: სამსვლიანების დაზეთვა | D28: — | F28: 0 | G28: IN-HOUSE | H28: IN PROCESS
A29: 25 | B29: სალნიკების შეცვლა | D29: — | F29: 0 | G29: IN-HOUSE | H29: IN PROCESS
A30: 26 | B30: პარკეტის აღება აბაზანაში | C30: კვ.მ | D30: — | E30: =განზომილებები!$E$16 -> 34.8 | F30: 0 | G30: IN-HOUSE | H30: DONE | I30: რაოდ. — იხ. „განზომილებები“ (34.8 კვ.მ); შიდა რესურსით
A31: 27 | B31: ნომრის და აბაზანის კარის დემონტაჟი, მონტაჟი | C31: ც. | D31: — | E31: 37 | F31: 0 | G31: IN-HOUSE | H31: DONE
A32: 28 | B32: კარის (209×83×4.5სმ) დაშპონვა, შეღებვა (რესტავრაცია) | C32: ც. | D32: 560 | E32: 19 | F32: =D32*E32 -> 10640 | G32: PAID | H32: IN PROCESS | I32: ფაქტობრივი კონტრაქტი; ბაზრის ორიენტირი სრული რესტავრაცია 250–500 ₾/კარი
A33: 29 | B33: კარის (209×70×4.5სმ) შეღებვა, რესტავრაცია | C33: ც. | D33: 343 | E33: 18 | F33: =D33*E33 -> 6174 | G33: PAID | H33: IN PROCESS | I33: ფაქტობრივი კონტრაქტი
A34: 30 | B34: შეღებილი MDF-ის პლინტუსი 15×1.6სმ (მასალა+მონტაჟი) | C34: მეტრი | D34: 20.7 | E34: 150 | F34: =D34*E34 -> 3105 | G34: PAID | H34: IN PROCESS | I34: ფაქტი
A35: 31 | B35: იატაკის დაგება (ფანერის და პარკეტის მონტაჟი) | C35: კვ.მ | D35: 40 | E35: 165 | F35: =D35*E35 -> 6600 | G35: UNPAID | H35: DONE | I35: შეთანხმებული 40 ₾/კვ.მ; ბაზარი: მხოლოდ პარკეტი 25–65 ₾
A36: 32 | B36: საწოლის თავთან პანელების გადამაგრება | D36: — | F36: 0 | G36: IN-HOUSE | H36: DONE
A37: 33 | B37: მილების შეფუთვა კონდენსატისთვის | D37: — | F37: 0 | G37: IN-HOUSE | H37: DONE
A38: 34 | B38: სიფონის გაწმენდა | D38: — | F38: 0 | G38: IN-HOUSE | H38: IN PROCESS
A39: 35 | B39: უნიტაზის რეზინის შეცვლა | D39: — | F39: 0 | G39: IN-HOUSE | H39: IN PROCESS
A40: 36 | B40: გერმეტიული სანათების მოხსნა, გაწმენდა | D40: — | F40: 0 | G40: IN-HOUSE | H40: IN PROCESS
A41: 37 | B41: შხაპის კაბინის დამზადება (1901) | C41: კვ.მ | D41: 300 | E41: 2.66 | F41: =D41*E41 -> 798 | G41: UNPAID | H41: IN PROCESS | I41: შეთანხმებული ≈800 ₾ (300 ₾/კვ.მ × 2.66 კვ.მ)
...

Sheet მასალები
B1: მასალები (შესყიდვები — ფაქტი და შეფასებები)
B2: PAID სტრიქონები — ფაქტობრივი ფასები; ცარიელი სტატუსით — შეფასება ბაზრის ფასით (13.08.2026).
A4: N | B4: მასალის დასახელება | C4: განზ. | D4: ერთ. ფასი (₾) | E4: რაოდ. | F4: ღირებულება (₾) | G4: გადახდა | H4: სტატუსი | I4: წყარო / შენიშვნა
A5: 1 | B5: თაბაშირმუყაო | C5: ცალი | D5: 17.5 | E5: 12 | F5: =D5*E5 -> 210 | G5: PAID | H5: DONE | I5: ფაქტი; ბაზარი: Knauf სტანდ. 15 ₾, ტენმედეგი 22.6 ₾ (domino.com.ge)
A6: 2 | B6: შურუფი 2×5 | C6: ყუთი | D6: 26 | E6: 1 | F6: =D6*E6 -> 26 | G6: PAID | H6: DONE
A7: 3 | B7: შურუფი 3×5 | C7: ყუთი | D7: 32 | E7: 1 | F7: =D7*E7 -> 32 | G7: PAID | H7: DONE
A8: 4 | B8: ცელოფანი | C8: რულონი | D8: 15 | E8: 40 | F8: =D8*E8 -> 600 | G8: PAID | H8: DONE | I8: ბაზარი 6–27 ₾/რულონი
A9: 5 | B9: კუთხოვანა თაბაშირმუყაოს კუთხისთვის | C9: ცალი | D9: 4 | E9: 20 | F9: =D9*E9 -> 80 | G9: PAID | H9: DONE
A10: 6 | B10: საფითხნი Knauf (სუფთა პირი) | C10: ტომარა | D10: 18 | E10: 2 | F10: =D10*E10 -> 36 | G10: PAID | H10: DONE | I10: ბაზარი: Fugagips 25კგ 20.35 ₾ (gorgia.ge)
A11: 7 | B11: სავარძლის და პუფის ქეჩები | C11: მეშოკი | D11: 2 | E11: 30 | F11: =D11*E11 -> 60 | G11: PAID | H11: DONE
A12: 8 | B12: მაკლავიცა დიდი იზოლაციისთვის | C12: ცალი | D12: 15 | E12: 1 | F12: =D12*E12 -> 15 | G12: PAID | H12: DONE
A13: 9 | B13: ქაღალდის სკოჩი | C13: ცალი | D13: 5.5 | E13: 30 | F13: =D13*E13 -> 165 | G13: PAID | H13: DONE | I13: ბაზარი 3–8 ₾ (domino.com.ge); რაოდენობა დასაზუსტებელია
A14: 10 | B14: ფილტრები ემლაიმიდან | C14: მეტრი | D14: 9 | E14: 20 | F14: =D14*E14 -> 180 | G14: PAID | H14: DONE
A15: 11 | B15: თეთრი საღებავი პანელისთვის (2.5 კგ) | C15: ცალი | D15: 75 | E15: 4 | F15: =D15*E15 -> 300 | G15: PAID | H15: DONE
A16: 12 | B16: მაგიდების შავი საღებავი (2-კომპონენტიანი) | C16: კგ | D16: 45 | E16: 6 | F16: =D16*E16 -> 270 | I16: შეფასება: 2K საღებავი ~36–60 ₾/ლ (grandmall.ge Novakril 2K); ძველში — „ველოდებით ფასს“
A17: 13 | B17: გერმანული აპარატის შკურკა 40-იანი | C17: ცალი | D17: 2.8 | E17: 100 | F17: =D17*E17 -> 280 | G17: PAID | H17: DONE | I17: ბაზარი: ზოგადი 1.05–1.95 ₾, Festool-კლასი ~4–5.5 ₾
A18: 14 | B18: გერმანული აპარატის შკურკა 60-იანი | C18: ცალი | D18: 2.8 | E18: 100 | F18: =D18*E18 -> 280 | G18: PAID | H18: DONE
A19: 15 | B19: გერმანული აპარატის შკურკა 80-იანი | C19: ცალი | D19: 2.8 | E19: 50 | F19: =D19*E19 -> 140 | G19: PAID | H19: DONE
A20: 16 | B20: გერმანული აპარატის შკურკა 120-იანი | C20: ცალი | D20: 2.8 | E20: 50 | F20: =D20*E20 -> 140 | G20: PAID | H20: DONE
A21: 17 | B21: სმესი შპაკლი | C21: ბალონი | D21: 18 | E21: 2 | F21: =D21*E21 -> 36
A22: 18 | B22: პარანიტის სალნიკები 20-ანი ფირატის | C22: ცალი | D22: 0.7 | E22: 100 | F22: =D22*E22 -> 70 | G22: PAID | H22: DONE
A23: 19 | B23: სილიკონი Würth გამჭვირვალე (SILSEAL 310მლ) | C23: ცალი | D23: 29 | E23: 20 | F23: =D23*E23 -> 580 | G23: PAID | H23: DONE | I23: ფაქტი; მიმდინარე ფასი 32 ₾ (shop.wurth.com.ge)
A24: 20 | B24: დანა | C24: ცალი | D24: 6 | E24: 10 | F24: =D24*E24 -> 60 | G24: PAID | H24: DONE | I24: ბაზარი 1.75–9.95 ₾
A25: 21 | B25: პირები | C25: ყუთი | D25: 3 | E25: 20 | F25: =D25*E25 -> 60 | G25: PAID | H25: DONE | I25: ბაზარი 1.85–4.5 ₾/10ც
A26: 22 | B26: ზეთი სპრეი (პეტლებისთვის) | C26: ცალი | D26: 32 | E26: 2 | F26: =D26*E26 -> 64 | G26: PAID | H26: DONE
A27: 23 | B27: ჟანგის მოსაშორებელი სპრეი WD-40 | C27: ცალი | D27: 12 | E27: 3 | F27: =D27*E27 -> 36 | G27: PAID | H27: DONE | I27: ფაქტი; მიმდინარე: 400მლ 18.1 ₾ (domino), 200მლ 15.2 ₾ (gorgia)
A28: 24 | B28: იზოლენტა | C28: ცალი | D28: 3 | E28: 10 | F28: =D28*E28 -> 30 | G28: PAID | H28: DONE | I28: ბაზარი 0.7–3.4 ₾
A29: 25 | B29: ჟანგის მოსაცილებელი | C29: ცალი | D29: 12 | E29: 1 | F29: =D29*E29 -> 12 | G29: PAID | H29: DONE
A30: 26 | B30: დეკორის გრძელბეწვიანი სატკეპნი | C30: ცალი | D30: 4 | E30: 2 | F30: =D30*E30 -> 8
A31: 27 | B31: ჩოთქები 5-ანი | C31: ცალი | D31: 6 | E31: 4 | F31: =D31*E31 -> 24 | G31: PAID | H31: DONE | I31: ბაზარი 2.5–5.95 ₾ (Color Expert)
A32: 28 | B32: იახტლაქი (შუშის ძირების და პადონისთვის) | C32: კგ | D32: 60 | E32: 4 | F32: =D32*E32 -> 240 | G32: PAID | H32: DONE | I32: ფაქტი — პრემიუმ კლასი; ბაზარი 24–50 ₾/კგ (gorgia, grandmall)
A33: 29 | B33: პატარა სატკეპნის პირები (დაბალი ბეწვით) | C33: ცალი | D33: 4 | E33: 15 | F33: =D33*E33 -> 60 | G33: PAID | H33: DONE
A34: 30 | B34: ფანკოილის მილების შესაფუთი ქეჩები (25-ანი) | C34: ცალი | D34: 8 | E34: 10 | F34: =D34*E34 -> 80 | G34: PAID | H34: DONE
A35: 31 | B35: შავი შესაფუთზე დასახვევი იზოლაცია | C35: ცალი | D35: 40 | E35: 2 | F35: =D35*E35 -> 80 | G35: PAID | H35: DONE
A36: 32 | B36: იმპულსური რელეები | C36: ცალი | D36: 75 | E36: 10 | F36: =D36*E36 -> 750 | G36: PAID | H36: DONE | I36: EU ფასი 47–62 ₾ + იმპორტი → 60–110 ₾; 75 ₾ რეალისტურია
A37: 33 | B37: წებო ცემენტი Kerakoll | C37: ტომარა | D37: 35 | E37: 15 | F37: =D37*E37 -> 525 | G37: PAID | H37: DONE | I37: იტალიური საცალო ≈38–39 ₾; დილერი — Espano (espano.ge)
A38: 34 | B38: ლაქი პრიალა (აეროზოლი) | C38: ბალონი | D38: 81.4 | E38: 86 | F38: =D38*E38 -> 7000.4 | G38: PAID | H38: DONE | I38: ფაქტი; ⚠ ბაზარი: აეროზოლი 20–32 ₾ (Novol 23 ₾, 17 ₾ 6+ ც.) — მომავალში დიდი ეკონომიაა შესაძლებელი
A39: 35 | B39: იზოლაცია Kerakoll (ჰიდროიზოლაცია 20კგ) | C39: ტომარა | D39: 230 | E39: 2 | F39: =D39*E39 -> 460 | G39: PAID | H39: DONE | I39: UK საცალო £67–73 ≈ 235–255 ₾ — ფასი რეალისტურია
A40: 36 | B40: პეპელა 4-ანი საფარდისთვის (რკინის) | C40: ცალი | D40: 0.85 | E40: 50 | F40: =D40*E40 -> 42.5 | G40: PAID | H40: DONE
A41: 37 | B41: პროფილი UD | C41: ყუთი | D41: 6 | E41: 24 | F41: =D41*E41 -> 144 | G41: PAID | H41: DONE
...

Sheet ინსტრუმენტები
B1: ინსტრუმენტები
A3: N | B3: დასახელება | C3: განზ. | D3: ერთ. ფასი (₾) | E3: რაოდ. | F3: ღირებულება (₾) | G3: გადახდა | H3: წყარო / შენიშვნა
A4: 1 | B4: პერფორატორი DeWalt პატარა (D25133K, SDS-Plus) | C4: ცალი | D4: 445 | E4: 1 | F4: =D4*E4 -> 445 | G4: UNPAID | H4: ოფიც. ფასი dewaltshop.ge (13.08.2026); ძველ ბიუჯეტში 695 ₾ — ეკონომია 250 ₾
A5: 2 | B5: პერფორატორი DeWalt დიდი (D25733K, SDS-Max) | C5: ცალი | D5: 2395 | E5: 1 | F5: =D5*E5 -> 2395 | G5: UNPAID | H5: ოფიც. ფასი dewaltshop.ge, მარაგშია; ძველში 2,990 ₾ — ეკონომია 595 ₾
A6: 3 | B6: პიკა პატარა პერფორატორისთვის (ბეტონის ასაფხეკი) | C6: ცალი | D6: 45 | E6: 2 | F6: =D6*E6 -> 90 | G6: PAID | H6: ფაქტი; მიმდინარე ბაზარი: Raider 4.8–11 ₾, DeWalt SDS-Max 19–30 ₾
B7: ჯამი | F7: =SUM(F4:F6) -> 2930

Sheet შემსრულებლები
B1: შემსრულებლები (გუნდები/ოსტატები)
B2: ზოგი პოზიცია უკვე ასახულია „სამუშაო“ ფურცელში — ჯამში ორმაგად არ ითვლება.
A4: N | B4: შემსრულებელი | C4: საგანი | D4: დღეები | E4: ღირებულება (₾) | F4: სამუშაო ცხრილში? | G4: შენიშვნა
A5: 1 | B5: ლომსაძე დ. | C5: ნომრებში ხის იატაკის დემონტაჟი | D5: 8 | E5: 500 | F5: კი — სამუშაო №16 | G5: იგივე 500 ₾ კონტრაქტი
A6: 2 | B6: მურვანიძე კ. | C6: აბაზანის იატაკის დემონტაჟი, აბაზანის ჭერის შეღებვა | D6: 10 | E6: 1000 | F6: არა
A7: 3 | C7: მალიარის დამხმარე | D7: 10 | E7: 1000 | F7: არა
A8: 4 | B8: ჯანგიძე გ. | C8: დურგალი (პადონის და შუშის ძირების შეცვლა) | D8: 16 | E8: 800 | F8: არა
A9: 5 | C9: ხალიჩის დაგება (მე-19 სართული) | E9: 1000 | F9: კი — სამუშაო №10 | G9: იგივე 1,000 ₾ კონტრაქტი
A10: 6 | B10: მიშა | C10: ფანჯრების სახელურების შემოწმება, შეკეთება | D10: 8 | E10: 400 | F10: კი — სამუშაო №20 | G10: იგივე 400 ₾ კონტრაქტი
C11: ჯამი | E11: =SUM(E5:E10) -> 4700
C12: აქედან უკვე „სამუშაო“ ცხრილშია | E12: =SUMIF(F5:F10,"კი*",E5:E10) -> 1900
C13: დამატებით ასახული ჯამურ ბიუჯეტში | E13: =E11-E12 -> 2800

Sheet განზომილებები
B1: განზომილებები (takeoffs) — იატაკები და სარკეები
A3: 1. ნომრის იატაკი
A4: ტიპი | B4: ოთახები | C4: კვ.მ/ოთახი | D4: რაოდ. | E4: სულ კვ.მ | F4: ფანერა (ც)
A5: Executive | B5: 1907; 1910 | C5: 26 | D5: 2 | E5: =C5*D5 -> 52 | F5: 20
A6: Standard | B6: 1901; 1902; 1909; 1916; 1918 | C6: 17 | D6: 5 | E6: =C6*D6 -> 85 | F6: 35
A7: Business | B7: 1919 | C7: 25 | D7: 1 | E7: =C7*D7 -> 25 | F7: 9
A8: ჯამი | D8: =SUM(D5:D7) -> 8 | E8: =SUM(E5:E7) -> 162 | F8: =SUM(F5:F7) -> 64
A10: 2. აბაზანის იატაკი
A11: ტიპი | B11: ოთახები | C11: კვ.მ/ოთახი | D11: რაოდ. | E11: სულ კვ.მ
A12: Executive | B12: 1904; 1907; 1910; 1917 | C12: 4.6 | D12: 4 | E12: =C12*D12 -> 18.4
A13: Standard | B13: 1903; 1906; 1908; 1912; 1916 | C13: 2.4 | D13: 5 | E13: =C13*D13 -> 12
A14: Business | B14: 1919 | C14: 2.4 | D14: 1 | E14: =C14*D14 -> 2.4
A15: Standard | B15: 1901 | C15: 2 | D15: 1 | E15: =C15*D15 -> 2
A16: ჯამი | D16: =SUM(D12:D15) -> 11 | E16: =SUM(E12:E15) -> 34.8
A19: 3. სარკეების შეცვლა
A20: ტიპი | B20: ოთახები | C20: ზომა (მ) | D20: რაოდ. | E20: სულ კვ.მ
A21: Standard | B21: 1902; 1909 | C21: 1.14 × 2.42 | D21: 2 | E21: =1.14*2.42*D21 -> 5.5176
A22: Standard | B22: 1901; 1916 | C22: 1.10 × 2.42 | D22: 2 | E22: =1.1*2.42*D22 -> 5.324
A23: ჯამი | D23: =SUM(D21:D22) -> 4 | E23: =SUM(E21:E22) -> 10.8416

Sheet წყაროები
B1: წყაროები — ფასების გადამოწმება (ბიბლიოგრაფია)
B2: ყველა წყარო შემოწმდა 13.08.2026. „გადამოწმებული“ = ფასი ნანახია ცოცხალ გვერდზე; „შეფასება“ = მიახლოება შედარებადი პოზიციებით.
A4: N | B4: კატეგორია | C4: წყარო | D4: URL | E4: რა გადამოწმდა | F4: სტატუსი
A5: 1 | B5: მაკრო | C5: საქართველოს ეროვნული ბანკი | D5: nbg.gov.ge/gw/api/ct/monetarypolicy/currencies/en/json | E5: EUR/GEL 3.0205; USD/GEL 2.6181 (13.08.2026) | F5: გადამოწმებული
A6: 2 | B6: მაკრო | C6: Geostat / TradingEconomics | D6: geostat.ge · tradingeconomics.com/georgia/inflation-cpi | E6: ინფლაცია ~4.3–5.5%; სამშენებლო ხარჯების ინდექსი | F6: გადამოწმებული
A7: 3 | B7: იატაკი | C7: parketi.ge | D7: parketi.ge/en/collections/oak-parquet | E7: მუხის მასიური პარკეტი: Rustic 75 / Select 99 / Exclusive 140 ₾/კვ.მ; ინჟინრული 179–269 ₾ | F7: გადამოწმებული
A8: 4 | B8: იატაკი | C8: ecowood.ge | D8: ecowood.ge | E8: ფანერა არყის 1525×1525: 8მმ 29 ₾, 10მმ 34 ₾, 12მმ 41 ₾; მასიური მუხა Extra 179 ₾ | F8: გადამოწმებული
A9: 5 | B9: იატაკი | C9: Bona Georgia (ოფიც.) | D9: bona.com.ge/parketis-laqi/ | E9: ლაქი Bona Mega EVO 380 ₾/5ლ ≈76 ₾/ლ; ხაზი 240–500 ₾ | F9: გადამოწმებული
A10: 6 | B10: იატაკი | C10: shop.glimtrex.ge | D10: shop.glimtrex.ge/ciklovka | E10: მოციკლოვება 20 ₾/კვ.მ; სრული ციკლი ლაქით 40–45 ₾/კვ.მ | F10: გადამოწმებული
A11: 7 | B11: იატაკი | C11: homeis.ge | D11: homeis.ge/iatakis-dageba/ | E11: პარკეტის დაგება: კომპანია 30–65 ₾, ოსტატი 25–60 ₾/კვ.მ | F11: ნაწილობრივ
A12: 8 | B12: იატაკი | C12: demontaji.ge | D12: demontaji.ge (2026 ტარიფები) | E12: პარკეტის აყრა 2 ₾/კვ.მ; ნაგვის გატანა ~370 ₾/მ³ | F12: გადამოწმებული
A13: 9 | B13: იატაკი | C13: domino.com.ge | D13: domino.com.ge — carpeting, mdf-plinth | E13: ბელგიური ხალიჩა 10.5–119 ₾/კვ.მ; MDF პლინტუსი 10–15.2 ₾/მ | F13: გადამოწმებული
A14: 10 | B14: იატაკი | C14: gurus.ge | D14: gurus.ge/remonti/laminatis-dageba | E14: ლამინატის დაგება 10–25 ₾/კვ.მ (ხალიჩის პროქსი) | F14: შეფასება
A15: 11 | B15: სანტექნიკა | C15: gorgia.ge | D15: gorgia.ge/ka/grohe/ | E15: Grohe შემრევები 187–306 ₾; ხელის შხაპი 63–103 ₾; Geberit სიფონი 70.5–87 ₾ | F15: გადამოწმებული
A16: 12 | B16: სანტექნიკა | C16: domino.com.ge | D16: domino.com.ge/en/grohe/ | E16: ზედა შხაპი AM.PM 250მმ 389 ₾; Grohe სისტემები 599–1275 ₾; Grohe კომპლექტი 159–180 ₾ | F16: გადამოწმებული
... A31: 27 | B31: ელექტრო | C31: lasma.eu / profelektro.lv (EU) | D31: lasma.eu · profelektro.lv | E31: იმპულსური რელე Acti9 iTL 14.8–19.7 € → 60–110 ₾ იმპორტით (საქ. ლისტინგი არ მოიძებნა) | F31: შეფასება
